WARNING 2019-01-04 14:33:40,784 base 152 Not Found: /
WARNING 2019-01-04 14:33:40,785 basehttp 124 "GET / HTTP/1.1" 404 2108
WARNING 2019-01-04 14:33:40,838 base 152 Not Found: /favicon.ico
WARNING 2019-01-04 14:33:40,839 basehttp 124 "GET /favicon.ico HTTP/1.1" 404 2159
WARNING 2019-01-04 14:33:54,017 base 152 Not Found: /sms_codes/137111111111/
WARNING 2019-01-04 14:33:54,019 basehttp 124 "GET /sms_codes/137111111111/ HTTP/1.1" 404 2195
INFO 2019-01-04 14:36:53,920 basehttp 124 "GET /sms_codes/15684575817/ HTTP/1.1" 200 9558
INFO 2019-01-04 14:36:53,947 basehttp 124 "GET /static/rest_framework/css/bootstrap.min.css HTTP/1.1" 304 0
INFO 2019-01-04 14:36:53,963 basehttp 124 "GET /static/rest_framework/css/prettify.css HTTP/1.1" 304 0
INFO 2019-01-04 14:36:53,965 basehttp 124 "GET /static/rest_framework/css/bootstrap-tweaks.css HTTP/1.1" 304 0
INFO 2019-01-04 14:36:53,971 basehttp 124 "GET /static/rest_framework/css/default.css HTTP/1.1" 304 0
INFO 2019-01-04 14:36:53,971 basehttp 124 "GET /static/rest_framework/js/default.js HTTP/1.1" 304 0
INFO 2019-01-04 14:36:53,973 basehttp 124 "GET /static/rest_framework/js/ajax-form.js HTTP/1.1" 304 0
INFO 2019-01-04 14:36:53,973 basehttp 124 "GET /static/rest_framework/js/csrf.js HTTP/1.1" 304 0
INFO 2019-01-04 14:36:53,989 basehttp 124 "GET /static/rest_framework/js/jquery-3.3.1.min.js HTTP/1.1" 304 0
INFO 2019-01-04 14:36:53,994 basehttp 124 "GET /static/rest_framework/img/grid.png HTTP/1.1" 304 0
INFO 2019-01-04 14:36:53,995 basehttp 124 "GET /static/rest_framework/js/bootstrap.min.js HTTP/1.1" 304 0
INFO 2019-01-04 14:36:54,013 basehttp 124 "GET /static/rest_framework/js/prettify-min.js HTTP/1.1" 304 0
INFO 2019-01-04 14:37:23,927 basehttp 124 "GET /sms_codes/15684575817/ HTTP/1.1" 200 9558
WARNING 2019-01-04 15:01:01,897 base 152 Not Found: /mobiles/15684575817/count/
WARNING 2019-01-04 15:01:01,898 basehttp 124 "GET /mobiles/15684575817/count/ HTTP/1.1" 404 2210
WARNING 2019-01-04 15:01:01,944 base 152 Not Found: /mobiles/15684575817/count/
WARNING 2019-01-04 15:01:01,947 basehttp 124 "GET /mobiles/15684575817/count/ HTTP/1.1" 404 2210
INFO 2019-01-04 15:01:02,214 basehttp 124 "GET /sms_codes/15684575817/ HTTP/1.1" 200 16
WARNING 2019-01-04 15:02:13,384 base 152 Not Found: /mobiles/15684575817/count/
WARNING 2019-01-04 15:02:13,385 basehttp 124 "GET /mobiles/15684575817/count/ HTTP/1.1" 404 2210
WARNING 2019-01-04 15:02:13,431 base 152 Not Found: /mobiles/15684575817/count/
WARNING 2019-01-04 15:02:13,435 basehttp 124 "GET /mobiles/15684575817/count/ HTTP/1.1" 404 2210
INFO 2019-01-04 15:02:13,720 basehttp 124 "GET /sms_codes/15684575817/ HTTP/1.1" 200 16
WARNING 2019-01-04 15:02:45,200 base 152 Not Found: /
WARNING 2019-01-04 15:02:45,201 basehttp 124 "GET / HTTP/1.1" 404 2108
INFO 2019-01-04 15:02:52,276 basehttp 124 "GET /sms_codes/15684575817/ HTTP/1.1" 200 9558
INFO 2019-01-04 15:03:02,794 basehttp 124 "GET /sms_codes/15684575817/ HTTP/1.1" 200 9558
INFO 2019-01-04 15:03:03,385 basehttp 124 "GET /sms_codes/15684575817/ HTTP/1.1" 200 9558
INFO 2019-01-04 15:03:03,574 basehttp 124 "GET /sms_codes/15684575817/ HTTP/1.1" 200 9558
INFO 2019-01-04 15:03:03,726 basehttp 124 "GET /sms_codes/15684575817/ HTTP/1.1" 200 9558
INFO 2019-01-04 15:03:03,878 basehttp 124 "GET /sms_codes/15684575817/ HTTP/1.1" 200 9558
INFO 2019-01-04 15:03:04,085 basehttp 124 "GET /sms_codes/15684575817/ HTTP/1.1" 200 9558
INFO 2019-01-04 15:03:04,263 basehttp 124 "GET /sms_codes/15684575817/ HTTP/1.1" 200 9558
INFO 2019-01-04 15:03:04,436 basehttp 124 "GET /sms_codes/15684575817/ HTTP/1.1" 200 9558
INFO 2019-01-04 15:03:04,647 basehttp 124 "GET /sms_codes/15684575817/ HTTP/1.1" 200 9558
INFO 2019-01-04 15:03:04,805 basehttp 124 "GET /sms_codes/15684575817/ HTTP/1.1" 200 9558
INFO 2019-01-04 15:03:04,987 basehttp 124 "GET /sms_codes/15684575817/ HTTP/1.1" 200 9558
INFO 2019-01-04 15:03:05,176 basehttp 124 "GET /sms_codes/15684575817/ HTTP/1.1" 200 9558
INFO 2019-01-04 15:33:43,124 basehttp 124 "GET /sms_codes/15684575817/ HTTP/1.1" 200 9558
WARNING 2019-01-04 15:33:43,868 basehttp 124 "GET /sms_codes/15684575817/ HTTP/1.1" 400 9583
WARNING 2019-01-04 15:33:47,299 basehttp 124 "GET /static/rest_framework/css/bootstrap.min.css.map HTTP/1.1" 404 1733
WARNING 2019-01-04 15:33:48,771 basehttp 124 "GET /sms_codes/15684575817/ HTTP/1.1" 400 9583
WARNING 2019-01-04 15:33:49,095 basehttp 124 "GET /static/rest_framework/css/bootstrap.min.css.map HTTP/1.1" 404 1733
INFO 2019-01-04 16:11:39,663 basehttp 124 "GET /sms_codes/15684575817/ HTTP/1.1" 200 9558
WARNING 2019-01-04 16:11:50,369 basehttp 124 "GET /sms_codes/15684575817/ HTTP/1.1" 400 9583
WARNING 2019-01-04 16:11:58,708 basehttp 124 "GET /sms_codes/15684575817/ HTTP/1.1" 400 9583
WARNING 2019-01-04 16:11:59,036 basehttp 124 "GET /sms_codes/15684575817/ HTTP/1.1" 400 9583
WARNING 2019-01-04 16:11:59,322 basehttp 124 "GET /sms_codes/15684575817/ HTTP/1.1" 400 9583
WARNING 2019-01-04 16:11:59,584 basehttp 124 "GET /sms_codes/15684575817/ HTTP/1.1" 400 9583
WARNING 2019-01-04 16:11:59,804 basehttp 124 "GET /sms_codes/15684575817/ HTTP/1.1" 400 9583
WARNING 2019-01-04 16:12:00,021 basehttp 124 "GET /sms_codes/15684575817/ HTTP/1.1" 400 9583
WARNING 2019-01-04 16:12:00,278 basehttp 124 "GET /sms_codes/15684575817/ HTTP/1.1" 400 9583
WARNING 2019-01-04 16:12:00,599 basehttp 124 "GET /sms_codes/15684575817/ HTTP/1.1" 400 9583
WARNING 2019-01-04 16:12:00,900 basehttp 124 "GET /sms_codes/15684575817/ HTTP/1.1" 400 9583
WARNING 2019-01-04 16:12:01,103 basehttp 124 "GET /sms_codes/15684575817/ HTTP/1.1" 400 9583
WARNING 2019-01-04 16:12:01,394 basehttp 124 "GET /sms_codes/15684575817/ HTTP/1.1" 400 9583
WARNING 2019-01-04 16:12:01,533 basehttp 124 "GET /sms_codes/15684575817/ HTTP/1.1" 400 9583
INFO 2019-01-04 16:12:47,083 basehttp 124 "GET /sms_codes/15684575817/ HTTP/1.1" 200 9558
WARNING 2019-01-04 16:12:52,899 basehttp 124 "GET /sms_codes/15684575817/ HTTP/1.1" 400 9583
INFO 2019-01-04 20:45:14,801 basehttp 124 "GET /usernames/wolaiziufo/count/ HTTP/1.1" 200 11
WARNING 2019-01-04 20:45:30,863 base 152 Not Found: /mobiles/15684575817/count/
WARNING 2019-01-04 20:45:30,865 basehttp 124 "GET /mobiles/15684575817/count/ HTTP/1.1" 404 2749
WARNING 2019-01-04 20:45:30,943 base 152 Not Found: /mobiles/15684575817/count/
WARNING 2019-01-04 20:45:30,945 basehttp 124 "GET /mobiles/15684575817/count/ HTTP/1.1" 404 2749
INFO 2019-01-04 20:45:31,121 basehttp 124 "GET /sms_codes/15684575817/ HTTP/1.1" 200 16
INFO 2019-01-04 20:46:06,012 basehttp 124 "OPTIONS /users/ HTTP/1.1" 200 0
INFO 2019-01-04 20:46:06,076 basehttp 124 "GET /mobiles/15684575817/count/ HTTP/1.1" 200 11
INFO 2019-01-04 20:46:06,086 basehttp 124 "GET /usernames/wolaiziufo/count/ HTTP/1.1" 200 11
ERROR 2019-01-04 20:48:49,705 exception 135 Internal Server Error: /users/
Traceback (most recent call last):
  File "/home/python/.virtualenvs/django17/lib/python3.5/site-packages/rest_framework/views.py", line 480, in dispatch
    response = handler(request, *args, **kwargs)
  File "/home/python/.virtualenvs/django17/lib/python3.5/site-packages/rest_framework/generics.py", line 192, in post
    return self.create(request, *args, **kwargs)
  File "/home/python/.virtualenvs/django17/lib/python3.5/site-packages/rest_framework/mixins.py", line 21, in create
    self.perform_create(serializer)
  File "/home/python/.virtualenvs/django17/lib/python3.5/site-packages/rest_framework/mixins.py", line 26, in perform_create
    serializer.save()
  File "/home/python/.virtualenvs/django17/lib/python3.5/site-packages/rest_framework/serializers.py", line 198, in save
    "You cannot call `.save()` after accessing `serializer.data`."
AssertionError: You cannot call `.save()` after accessing `serializer.data`.If you need to access data before committing to the database then inspect 'serializer.validated_data' instead. 

During handling of the above exception, another exception occurred:

Traceback (most recent call last):
  File "/home/python/.virtualenvs/django17/lib/python3.5/site-packages/rest_framework/settings.py", line 183, in import_from_string
    module = import_module(module_path)
  File "/home/python/.virtualenvs/django17/lib/python3.5/importlib/__init__.py", line 126, in import_module
    return _bootstrap._gcd_import(name[level:], package, level)
  File "<frozen importlib._bootstrap>", line 986, in _gcd_import
  File "<frozen importlib._bootstrap>", line 969, in _find_and_load
  File "<frozen importlib._bootstrap>", line 944, in _find_and_load_unlocked
  File "<frozen importlib._bootstrap>", line 222, in _call_with_frames_removed
  File "<frozen importlib._bootstrap>", line 986, in _gcd_import
  File "<frozen importlib._bootstrap>", line 969, in _find_and_load
  File "<frozen importlib._bootstrap>", line 944, in _find_and_load_unlocked
  File "<frozen importlib._bootstrap>", line 222, in _call_with_frames_removed
  File "<frozen importlib._bootstrap>", line 986, in _gcd_import
  File "<frozen importlib._bootstrap>", line 969, in _find_and_load
  File "<frozen importlib._bootstrap>", line 956, in _find_and_load_unlocked
ImportError: No module named 'meiduo_mall'

During handling of the above exception, another exception occurred:

Traceback (most recent call last):
  File "/home/python/.virtualenvs/django17/lib/python3.5/site-packages/django/core/handlers/exception.py", line 41, in inner
    response = get_response(request)
  File "/home/python/.virtualenvs/django17/lib/python3.5/site-packages/django/core/handlers/base.py", line 187, in _get_response
    response = self.process_exception_by_middleware(e, request)
  File "/home/python/.virtualenvs/django17/lib/python3.5/site-packages/django/core/handlers/base.py", line 185, in _get_response
    response = wrapped_callback(request, *callback_args, **callback_kwargs)
  File "/home/python/.virtualenvs/django17/lib/python3.5/site-packages/django/views/decorators/csrf.py", line 58, in wrapped_view
    return view_func(*args, **kwargs)
  File "/home/python/.virtualenvs/django17/lib/python3.5/site-packages/django/views/generic/base.py", line 68, in view
    return self.dispatch(request, *args, **kwargs)
  File "/home/python/.virtualenvs/django17/lib/python3.5/site-packages/rest_framework/views.py", line 483, in dispatch
    response = self.handle_exception(exc)
  File "/home/python/.virtualenvs/django17/lib/python3.5/site-packages/rest_framework/views.py", line 437, in handle_exception
    exception_handler = self.get_exception_handler()
  File "/home/python/.virtualenvs/django17/lib/python3.5/site-packages/rest_framework/views.py", line 288, in get_exception_handler
    return self.settings.EXCEPTION_HANDLER
  File "/home/python/.virtualenvs/django17/lib/python3.5/site-packages/rest_framework/settings.py", line 227, in __getattr__
    val = perform_import(val, attr)
  File "/home/python/.virtualenvs/django17/lib/python3.5/site-packages/rest_framework/settings.py", line 170, in perform_import
    return import_from_string(val, setting_name)
  File "/home/python/.virtualenvs/django17/lib/python3.5/site-packages/rest_framework/settings.py", line 187, in import_from_string
    raise ImportError(msg)
ImportError: Could not import 'meiduo_mall.utils.exceptions.exception_handler' for API setting 'EXCEPTION_HANDLER'. ImportError: No module named 'meiduo_mall'.
ERROR 2019-01-04 20:49:01,785 basehttp 124 "POST /users/ HTTP/1.1" 500 139082
INFO 2019-01-04 20:53:52,055 basehttp 124 "GET /mobiles/15684575817/count/ HTTP/1.1" 200 11
INFO 2019-01-04 20:53:52,060 basehttp 124 "GET /usernames/wolaiziufo/count/ HTTP/1.1" 200 11
ERROR 2019-01-04 20:53:52,063 exception 135 Internal Server Error: /users/
Traceback (most recent call last):
  File "/home/python/.virtualenvs/django17/lib/python3.5/site-packages/rest_framework/views.py", line 480, in dispatch
    response = handler(request, *args, **kwargs)
  File "/home/python/.virtualenvs/django17/lib/python3.5/site-packages/rest_framework/generics.py", line 192, in post
    return self.create(request, *args, **kwargs)
  File "/home/python/.virtualenvs/django17/lib/python3.5/site-packages/rest_framework/mixins.py", line 20, in create
    serializer.is_valid(raise_exception=True)
  File "/home/python/.virtualenvs/django17/lib/python3.5/site-packages/rest_framework/serializers.py", line 244, in is_valid
    raise ValidationError(self.errors)
rest_framework.exceptions.ValidationError: {'non_field_errors': [ErrorDetail(string='短信失效', code='invalid')]}

During handling of the above exception, another exception occurred:

Traceback (most recent call last):
  File "/home/python/.virtualenvs/django17/lib/python3.5/site-packages/rest_framework/settings.py", line 183, in import_from_string
    module = import_module(module_path)
  File "/home/python/.virtualenvs/django17/lib/python3.5/importlib/__init__.py", line 126, in import_module
    return _bootstrap._gcd_import(name[level:], package, level)
  File "<frozen importlib._bootstrap>", line 986, in _gcd_import
  File "<frozen importlib._bootstrap>", line 969, in _find_and_load
  File "<frozen importlib._bootstrap>", line 944, in _find_and_load_unlocked
  File "<frozen importlib._bootstrap>", line 222, in _call_with_frames_removed
  File "<frozen importlib._bootstrap>", line 986, in _gcd_import
  File "<frozen importlib._bootstrap>", line 969, in _find_and_load
  File "<frozen importlib._bootstrap>", line 944, in _find_and_load_unlocked
  File "<frozen importlib._bootstrap>", line 222, in _call_with_frames_removed
  File "<frozen importlib._bootstrap>", line 986, in _gcd_import
  File "<frozen importlib._bootstrap>", line 969, in _find_and_load
  File "<frozen importlib._bootstrap>", line 956, in _find_and_load_unlocked
ImportError: No module named 'meiduo_mall'

During handling of the above exception, another exception occurred:

Traceback (most recent call last):
  File "/home/python/.virtualenvs/django17/lib/python3.5/site-packages/django/core/handlers/exception.py", line 41, in inner
    response = get_response(request)
  File "/home/python/.virtualenvs/django17/lib/python3.5/site-packages/django/core/handlers/base.py", line 187, in _get_response
    response = self.process_exception_by_middleware(e, request)
  File "/home/python/.virtualenvs/django17/lib/python3.5/site-packages/django/core/handlers/base.py", line 185, in _get_response
    response = wrapped_callback(request, *callback_args, **callback_kwargs)
  File "/home/python/.virtualenvs/django17/lib/python3.5/site-packages/django/views/decorators/csrf.py", line 58, in wrapped_view
    return view_func(*args, **kwargs)
  File "/home/python/.virtualenvs/django17/lib/python3.5/site-packages/django/views/generic/base.py", line 68, in view
    return self.dispatch(request, *args, **kwargs)
  File "/home/python/.virtualenvs/django17/lib/python3.5/site-packages/rest_framework/views.py", line 483, in dispatch
    response = self.handle_exception(exc)
  File "/home/python/.virtualenvs/django17/lib/python3.5/site-packages/rest_framework/views.py", line 437, in handle_exception
    exception_handler = self.get_exception_handler()
  File "/home/python/.virtualenvs/django17/lib/python3.5/site-packages/rest_framework/views.py", line 288, in get_exception_handler
    return self.settings.EXCEPTION_HANDLER
  File "/home/python/.virtualenvs/django17/lib/python3.5/site-packages/rest_framework/settings.py", line 227, in __getattr__
    val = perform_import(val, attr)
  File "/home/python/.virtualenvs/django17/lib/python3.5/site-packages/rest_framework/settings.py", line 170, in perform_import
    return import_from_string(val, setting_name)
  File "/home/python/.virtualenvs/django17/lib/python3.5/site-packages/rest_framework/settings.py", line 187, in import_from_string
    raise ImportError(msg)
ImportError: Could not import 'meiduo_mall.utils.exceptions.exception_handler' for API setting 'EXCEPTION_HANDLER'. ImportError: No module named 'meiduo_mall'.
ERROR 2019-01-04 20:53:52,148 basehttp 124 "POST /users/ HTTP/1.1" 500 133969
INFO 2019-01-04 20:54:20,362 basehttp 124 "GET /mobiles/15684575817/count/ HTTP/1.1" 200 11
INFO 2019-01-04 20:54:20,408 basehttp 124 "GET /sms_codes/15684575817/ HTTP/1.1" 200 16
INFO 2019-01-04 20:54:38,911 basehttp 124 "GET /mobiles/15684575817/count/ HTTP/1.1" 200 11
INFO 2019-01-04 20:54:38,920 basehttp 124 "GET /usernames/wolaiziufo/count/ HTTP/1.1" 200 11
INFO 2019-01-04 20:54:38,999 basehttp 124 "POST /users/ HTTP/1.1" 201 157
